Workbook

Sheet Assumptions
A1: ALPHABET (GOOGL)
A2: Inputs and Assumptions | R2: Notes
R3: 1) | S3: Since specific metrics are not given for Youtube ad revenue, subscritption/platforms/devices revenue, Cloud Services or Other Bets, I will use historical growth rates for Google blended with competitors' growth rates
S4: when determining how that revenue will grow over time
B5: General
B6: - | C6: First Year of forecast: | H6: 2025 | R6: 2) | T6: 2022 | U6: 2023 | V6: 2024 | W6: avg
S7: P.C | T7: 0.1 | U7: 0.07 | V7: 0.05 | W7: =AVERAGE(T7:V7) -> 0.073333333 | Y7: Growth for google search revenue has been increasing mainly from cpc growth, I will assume that future paid click growth will
B8: - | C8: The key drivers that will be used when modeling will be | S8: C.P.C | T8: -0.01 | U8: 0.01 | V8: 0.07 | W8: =AVERAGE(T8:V8) -> 0.023333333 | Y8: grow at a terminal rate growth of about 3% and then cost-per-click will increase in the near future due to continued inflation but slow eventually to 2% general inflation
C9: paid click growth, cost-per-click change (these are | S9: I.C | T9: 0.03 | U9: -0.05 | V9: -0.11 | W9: =AVERAGE(T9:V9) -> -0.043333333 | Y9: Given overall lack of growth, I will assume google network revenue will likely be flat
C10: for google search), impression change, | S10: C.P.I | T10: 0.01 | U10: 0 | V10: 0.1 | W10: =AVERAGE(T10:V10) -> 0.036666667
C11: cost-per-impression change (these are for google network)
S12: YT ads | T12: =(29243-28845)/28845 -> 0.013797885 | U12: =31510/29243 - 1 -> 0.077522826 | V12: =36147/31510 - 1 -> 0.14715963 | W12: =AVERAGE(T12:V12) -> 0.079493448 | Y12: Growth for YT ad revenue is primarily driver by increase yt short interaction and ad spending increases, and will likely continue to increase
B13: Google Search Revenue Growth Forecast | Y13: in the near future but then converge to about 12.5% which is the average cagr for the global digital ad market
D14: 2025 | E14: 2026 | F14: 2027 | G14: 2028 | H14: 2029 | S14: Subscription | T14: =29055/28032 - 1 -> 0.036494007 | U14: =34688/29055 - 1 -> 0.19387369 | V14: =40340/34688 - 1 -> 0.16293819 | W14: =AVERAGE(T14:V14) -> 0.13110196 | Y14: Likely downtrend from here as subscription and device ownership market matures, likely converges to a 5% growth rate (2 inflatioon 3 real growth)
B15: Base Case | D15: 0.12 | E15: 0.1 | F15: 0.08 | G15: 0.06 | H15: 0.05
J16: Interest Rates | S16: Cloud | T16: =26280/19206 - 1 -> 0.3683224 | U16: =33088/26280 - 1 -> 0.25905632 | V16: =43229/33088 - 1 -> 0.30648574 | W16: =AVERAGE(T16:V16) -> 0.31128815 | Y16: likely grow at a similar rate for the next couple of years then slow down to the high teens like aws
B17: Google Network Revenue Growth Forecast | J17: Interest on revolver | M17: n/a
D18: 2025 | E18: 2026 | F18: 2027 | G18: 2028 | H18: 2029 | J18: Interest on ST debt | M18: 0.044 | S18: Other Bets | T18: =1068/753 -1 -> 0.41832669 | U18: =1527/1068 - 1 -> 0.42977528 | V18: =1648/1527 - 1 -> 0.079240341 | W18: =AVERAGE(T18:V18) -> 0.3091141 | Y18: will use average grow rate as this is a tiny piece of revenue growth
B19: Base Case | D19: -0.01 | E19: -0.01 | F19: -0.01 | G19: -0.01 | H19: -0.01 | J19: Interest rate on LT debt | M19: 0.032 | R19: 3) | S19: 4.4% st debt interest rate as seen on balance sheet, due to large issuance of lt debt, I will assume that once this is paid no st debt will be issued until after the scope of this model. 3.2% weighted average of
S20: long term debt outstanding as seen on most recent 10q, using the assumption that when an interest rate is given as a range, the average interest rate paid will be closer to the upper exteme due to most debt
B21: Youtube Ad Revenue Growth Forecast | S21: being outstanding until 2050+. Also, it seems Google issues lt debt about once every 4-5 years so I will also assume no new lt debt until after the scope of this model
D22: 2025 | E22: 2026 | F22: 2027 | G22: 2028 | H22: 2029 | J22: Taxes
B23: Base Case | D23: 0.17 | E23: 0.18 | F23: 0.16 | G23: 0.14 | H23: 0.12 | J23: Corporate tax rate | M23: 0.21
J24: Effective tax rate | M24: 0.16 | R24: 4) Effective tax rate of 16% estimated based off last 3 yeards effective tax rates
B25: S.P.D Revenue Growth Forecast
D26: 2025 | E26: 2026 | F26: 2027 | G26: 2028 | H26: 2029 | R26: 5) | S26: EBIT margins are unlikely to improve due to significantly larger spending in CapEx and subsequent depreciation/R&D/SG&A costs associated with it offsetting the larger revenue gains
B27: Base Case | D27: 0.13 | E27: 0.1 | F27: 0.08 | G27: 0.06 | H27: 0.05
R28: 6) | S28: In 2023, reporting of depreciation and amortisation CFS changed. Amortization schedule was included in 10Q of 03/2023
B29: Cloud Services Revenue Growth Forecast
D30: 2025 | E30: 2026 | F30: 2027 | G30: 2028 | H30: 2029 | R30: 7) | S30: Assuming that by 2029, Capex as a % of Revenue decreases to Amazon's levels of about 13%
B31: Base Case | D31: 0.35 | E31: 0.3 | F31: 0.26 | G31: 0.22 | H31: 0.18
R32: 8) | S32: Assume D&A as % of Capex grows in proportion is growth in Capex as a % of revenue
B33: Other Bets Revenue Growth Forecast
D34: 2025 | E34: 2026 | F34: 2027 | G34: 2028 | H34: 2029
B35: Base Case | D35: 0.309 | E35: 0.309 | F35: 0.309 | G35: 0.309 | H35: 0.309

Sheet Comparable Analysis
A1: Company

Sheet Scenarios
A1: Google
A2: Sales and Cost Scenarios
B6: Scenario Switch | D6: 2 | G6: 2025 | H6: 2026 | I6: 2027 | J6: 2028 | K6: 2029
B10: Google Search Revenue Growth Forecast | G10: =CHOOSE($D$6, G12,G13,G14) -> 0.12 | H10: =CHOOSE($D$6, H12,H13,H14) -> 0.1 | I10: =CHOOSE($D$6, I12,I13,I14) -> 0.08 | J10: =CHOOSE($D$6, J12,J13,J14) -> 0.06 | K10: =CHOOSE($D$6, K12,K13,K14) -> 0.05
B12: Best Case | G12: 0.14 | H12: 0.12 | I12: 0.1 | J12: 0.08 | K12: 0.07
B13: Base Case | G13: 0.12 | H13: 0.1 | I13: 0.08 | J13: 0.06 | K13: 0.05
B14: Worst Case | G14: 0.1 | H14: 0.08 | I14: 0.06 | J14: 0.04 | K14: 0.03
B16: Google Network Revenue Growth Forecast | G16: =CHOOSE($D$6, G18,G19,G20) -> -0.01 | H16: =CHOOSE($D$6, H18,H19,H20) -> -0.01 | I16: =CHOOSE($D$6, I18,I19,I20) -> -0.01 | J16: =CHOOSE($D$6, J18,J19,J20) -> -0.01 | K16: =CHOOSE($D$6, K18,K19,K20) -> -0.01
B18: Best Case | G18: -0.01 | H18: 0 | I18: 0.01 | J18: 0.02 | K18: 0.04
B19: Base Case | G19: -0.01 | H19: -0.01 | I19: -0.01 | J19: -0.01 | K19: -0.01
B20: Worst Case | G20: -0.02 | H20: -0.03 | I20: -0.03 | J20: -0.05 | K20: -0.1
B22: Youtube Ad Revenue Growth Forecast | G22: =CHOOSE($D$6, G24,G25,G26) -> 0.15 | H22: =CHOOSE($D$6, H24,H25,H26) -> 0.14 | I22: =CHOOSE($D$6, I24,I25,I26) -> 0.13 | J22: =CHOOSE($D$6, J24,J25,J26) -> 0.12 | K22: =CHOOSE($D$6, K24,K25,K26) -> 0.12
B24: Best Case | G24: 0.18 | H24: 0.21 | I24: 0.2 | J24: 0.18 | K24: 0.16
B25: Base Case | G25: 0.15 | H25: 0.14 | I25: 0.13 | J25: 0.12 | K25: 0.12
B26: Worst Case | G26: 0.14 | H26: 0.13 | I26: 0.12 | J26: 0.1 | K26: 0.1
B28: S.P.D Revenue Growth Forecast | G28: =CHOOSE($D$6, G30,G31,G32) -> 0.13 | H28: =CHOOSE($D$6, H30,H31,H32) -> 0.1 | I28: =CHOOSE($D$6, I30,I31,I32) -> 0.08 | J28: =CHOOSE($D$6, J30,J31,J32) -> 0.06 | K28: =CHOOSE($D$6, K30,K31,K32) -> 0.05
B30: Best Case | G30: 0.16 | H30: 0.14 | I30: 0.11 | J30: 0.09 | K30: 0.07
B31: Base Case | G31: 0.13 | H31: 0.1 | I31: 0.08 | J31: 0.06 | K31: 0.05
B32: Worst Case | G32: 0.13 | H32: 0.09 | I32: 0.06 | J32: 0.04 | K32: 0.02
B34: Cloud Services Revenue Growth Forecast | G34: =CHOOSE($D$6, G36,G37,G38) -> 0.35 | H34: =CHOOSE($D$6, H36,H37,H38) -> 0.3 | I34: =CHOOSE($D$6, I36,I37,I38) -> 0.26 | J34: =CHOOSE($D$6, J36,J37,J38) -> 0.22 | K34: =CHOOSE($D$6, K36,K37,K38) -> 0.18
B36: Best Case | G36: 0.38 | H36: 0.33 | I36: 0.29 | J36: 0.25 | K36: 0.22
B37: Base Case | G37: 0.35 | H37: 0.3 | I37: 0.26 | J37: 0.22 | K37: 0.18
B38: Worst Case | G38: 0.27 | H38: 0.2 | I38: 0.15 | J38: 0.12 | K38: 0.1
B40: Other Bets Revenue Growth Forecast | G40: =CHOOSE($D$6, G42,G43,G44) -> 0.309 | H40: =CHOOSE($D$6, H42,H43,H44) -> 0.309 | I40: =CHOOSE($D$6, I42,I43,I44) -> 0.309 | J40: =CHOOSE($D$6, J42,J43,J44) -> 0.309 | K40: =CHOOSE($D$6, K42,K43,K44) -> 0.309
B42: Best Case | G42: 0.4 | H42: 0.4 | I42: 0.4 | J42: 0.4 | K42: 0.4
B43: Base Case | G43: 0.309 | H43: 0.309 | I43: 0.309 | J43: 0.309 | K43: 0.309
B44: Worst Case | G44: 0.1 | H44: 0.1 | I44: 0.1 | J44: 0.1 | K44: 0.1

Sheet Financial Modeling + DCF
B2: Financial Modeling
C4: Ticker | D4: GOOGL | G4: Implied Share Price
C5: Date | D5: 45951 | G5: Current Share Price
C6: Year-End | D6: 46022
B8: INCOME STATEMENT
G9: 2022 | H9: 2023 | I9: 2024 | J9: 2025 | K9: 2026 | L9: 2027 | M9: 2028 | N9: 2029
B10: Revenue
C11: Google Search | G11: 162450 | H11: 175003 | I11: 198084 | J11: =I11*(1+J12) -> 221854.08 | K11: =J11*(1+K12) -> 244039.49 | L11: =K11*(1+L12) -> 263562.65 | M11: =L11*(1+M12) -> 279376.41 | N11: =M11*(1+N12) -> 293345.23
C12: % growth | G12: =162450/148961 - 1 -> 0.090553903 | H12: =H11/G11 - 1 -> 0.077273007 | I12: =I11/H11 - 1 -> 0.13188917 | J12: =Scenarios!G10 -> 0.12 | K12: =Scenarios!H10 -> 0.1 | L12: =Scenarios!I10 -> 0.08 | M12: =Scenarios!J10 -> 0.06 | N12: =Scenarios!K10 -> 0.05
C13: Google Network | G13: 32780 | H13: 31312 | I13: 30359 | J13: =I13*(1+J14) -> 30055.41 | K13: =J13*(1+K14) -> 29754.856 | L13: =K13*(1+L14) -> 29457.307 | M13: =L13*(1+M14) -> 29162.734 | N13: =M13*(1+N14) -> 28871.107
C14: % growth | G14: =G13/31701 - 1 -> 0.034036781 | H14: =H13/G13 - 1 -> -0.044783405 | I14: =I13/H13 - 1 -> -0.030435616 | J14: =Scenarios!G16 -> -0.01 | K14: =Scenarios!H16 -> -0.01 | L14: =Scenarios!I16 -> -0.01 | M14: =Scenarios!J16 -> -0.01 | N14: =Scenarios!K16 -> -0.01
C15: Youtube Ads | G15: 29243 | H15: 31510 | I15: 36147 | J15: =I15*(1+J16) -> 41569.05 | K15: =J15*(1+K16) -> 47388.717 | L15: =K15*(1+L16) -> 53549.25 | M15: =L15*(1+M16) -> 59975.16 | N15: =M15*(1+N16) -> 67172.179
C16: % growth | G16: =G15/28845 - 1 -> 0.013797885 | H16: =H15/G15 - 1 -> 0.077522826 | I16: =I15/H15 - 1 -> 0.14715963 | J16: =Scenarios!G22 -> 0.15 | K16: =Scenarios!H22 -> 0.14 | L16: =Scenarios!I22 -> 0.13 | M16: =Scenarios!J22 -> 0.12 | N16: =Scenarios!K22 -> 0.12
C17: Subscription/Platforms/Devices | G17: 29055 | H17: 34688 | I17: 40340 | J17: =I17*(1+J18) -> 45584.2 | K17: =J17*(1+K18) -> 50142.62 | L17: =K17*(1+L18) -> 54154.03 | M17: =L17*(1+M18) -> 57403.271 | N17: =M17*(1+N18) -> 60273.435
C18: % growth | G18: =G17/28032 - 1 -> 0.036494007 | H18: =H17/G17 - 1 -> 0.19387369 | I18: =I17/H17 - 1 -> 0.16293819 | J18: =Scenarios!G28 -> 0.13 | K18: =Scenarios!H28 -> 0.1 | L18: =Scenarios!I28 -> 0.08 | M18: =Scenarios!J28 -> 0.06 | N18: =Scenarios!K28 -> 0.05
C19: Cloud Services | G19: 26280 | H19: 33088 | I19: 43229 | J19: =I19*(1+J20) -> 58359.15 | K19: =J19*(1+K20) -> 75866.895 | L19: =K19*(1+L20) -> 95592.288 | M19: =L19*(1+M20) -> 116622.59 | N19: =M19*(1+N20) -> 137614.66
C20: % growth | G20: =G19/19206 - 1 -> 0.3683224 | H20: =H19/G19 - 1 -> 0.25905632 | I20: =I19/H19 - 1 -> 0.30648574 | J20: =Scenarios!G34 -> 0.35 | K20: =Scenarios!H34 -> 0.3 | L20: =Scenarios!I34 -> 0.26 | M20: =Scenarios!J34 -> 0.22 | N20: =Scenarios!K34 -> 0.18
C21: Other Bets | G21: 1068 | H21: 1527 | I21: 1648 | J21: =I21*(1+J22) -> 2157.232 | K21: =J21*(1+K22) -> 2823.8167 | L21: =K21*(1+L22) -> 3696.376 | M21: =L21*(1+M22) -> 4838.5562 | N21: =M21*(1+N22) -> 6333.6701
C22: % growth | G22: =G21/753 - 1 -> 0.41832669 | H22: =H21/G21 - 1 -> 0.42977528 | I22: =I21/H21 - 1 -> 0.079240341 | J22: =Scenarios!G40 -> 0.309 | K22: =Scenarios!H40 -> 0.309 | L22: =Scenarios!I40 -> 0.309 | M22: =Scenarios!J40 -> 0.309 | N22: =Scenarios!K40 -> 0.309
B23: Total Revenue | G23: =G11+G13+G15+G17+G19+G21 -> 280876 | H23: =H11+H13+H15+H17+H19+H21 -> 307128 | I23: =I11+I13+I15+I17+I19+I21 -> 349807 | J23: =J11+J13+J15+J17+J19+J21 -> 399579.12 | K23: =K11+K13+K15+K17+K19+K21 -> 450016.39 | L23: =L11+L13+L15+L17+L19+L21 -> 500011.9 | M23: =M11+M13+M15+M17+M19+M21 -> 547378.72 | N23: =N11+N13+N15+N17+N19+N21 -> 593610.27
C24: % growth | G24: =G23/257637 - 1 -> 0.090200553 | H24: =H23/G23 - 1 -> 0.093464732 | I24: =I23/H23 - 1 -> 0.13896161 | J24: =J23/I23 - 1 -> 0.14228452 | K24: =K23/J23 - 1 -> 0.12622599 | L24: =L23/K23 - 1 -> 0.11109708 | M24: =M23/L23 - 1 -> 0.094731388 | N24: =N23/M23 - 1 -> 0.084459908
B26: EBIT | G26: 74842 | H26: 84293 | I26: 112390 | J26: =J23*J27 -> 111882.15 | K26: =K23*K27 -> 117004.26 | L26: =L23*L27 -> 135003.21 | M26: =M23*M27 -> 147792.25 | N26: =N23*N27 -> 142466.47 | Q26: =J23*0.321 -> 128264.9 | R26: =K23*0.321 -> 144455.26 | S26: =L23*0.321 -> 160503.82 | T26: =M23*0.321 -> 175708.57 | U26: =N23*0.321 -> 190548.9
C27: % of revenue | G27: =G26/G23 -> 0.26645922 | H27: =H26/H23 -> 0.2744556 | I27: =I26/I23 -> 0.32129146 | J27: 0.28 | K27: 0.26 | L27: 0.27 | M27: 0.27 | N27: 0.24 | Q27: 20000 | R27: 35000 | S27: 30000 | T27: 25000 | U27: 15000
Q28: =Q26-Q27 -> 108264.9 | R28: =R26-R27 -> 109455.26 | S28: =S26-S27 -> 130503.82 | T28: =T26-T27 -> 150708.57 | U28: =U26-U27 -> 175548.9
B29: Taxes | G29: 11356 | H29: 11922 | I29: 19697 | J29: =J30*J26 -> 17469.43 | K29: =K30*K26 -> 18441.134 | L29: =L30*L26 -> 22005.881 | M29: =M30*M26 -> 23486.888 | N29: =N30*N26 -> 22772.395
C30: % of EBIT | G30: =G29/G26 -> 0.15173298 | H30: =H29/H26 -> 0.14143523 | I30: =I29/I26 -> 0.17525581 | J30: =AVERAGE(G30:I30) -> 0.15614134 | K30: =AVERAGE(H30:J30) -> 0.15761079 | L30: =AVERAGE(I30:K30) -> 0.16300265 | M30: =AVERAGE(J30:L30) -> 0.15891826 | N30: =AVERAGE(K30:M30) -> 0.1598439
B32: CASH FLOW ITEMS
B33: D&A | G33: =13475+641 -> 14116 | H33: =11946+343+126 -> 12415 | I33: =443+15311 -> 15754 | J33: =J37*J35 -> 36104.134 | K33: =K37*K35 -> 51693.773 | L33: =L37*L35 -> 47881.139 | M33: =M37*M35 -> 40333.169 | N33: =N37*N35 -> 32853.378
C34: % of revenue | G34: =G33/G23 -> 0.050257053 | H34: =H33/H23 -> 0.040422886 | I34: =I33/I23 -> 0.045036263 | J34: =J33/J23 -> 0.090355405 | K34: =K33/K23 -> 0.11487087 | L34: =L33/L23 -> 0.09576 | M34: =M33/M23 -> 0.073684211 | N34: =N33/N23 -> 0.055345029
C35: % of capex | G35: =G33/G37 -> 0.44834048 | H35: =H33/H37 -> 0.3849493 | I35: =I33/I37 -> 0.29987627 | J35: =I35*(1+(J38/I38 - 1)) -> 0.42475451 | K35: 0.54 | L35: 0.56 | M35: =L35*(1+(M38/L38 - 1)) -> 0.49122807 | N35: =M35*(1+(N38/M38 - 1)) -> 0.42573099
B37: Capex | G37: 31485 | H37: 32251 | I37: 52535 | J37: 85000 | K37: =K23*K38 -> 95729.209 | L37: =L23*L38 -> 85502.035 | M37: =M23*M38 -> 82106.808 | N37: =N23*N38 -> 77169.336 | P37: note: 2025 85B capex from report
C38: % of revenue | G38: =G37/G23 -> 0.11209573 | H38: =H37/H23 -> 0.10500834 | I38: =I37/I23 -> 0.15018282 | J38: =J37/J23 -> 0.21272383 | K38: =J38 -> 0.21272383 | L38: 0.171 | M38: 0.15 | N38: 0.13
B40: Change in NWC | G40: =-2317 +584 - 5046 + 707 +3915 - 445 + 367 -> -2235 | H40: =-7833 + 523 - 2143 +664 + 3937 +482 + 525 -> -3845 | I40: =-5891 - 2418 - 1397 + 359 - 1161 + 1059 + 1043 -> -8406 | J40: =J41*J23 -> -7487.499 | K40: =K41*K23 -> -7480.8931 | L40: =L41*L23 -> -7315.7574 | M40: =M41*M23 -> -6829.0161 | N40: =N41*N23 -> -6602.803
C41: % of revenue | G41: =G40/G23 -> -0.007957248 | H41: =H40/H23 -> -0.01251921 | I41: =I40/I23 -> -0.024030394 | J41: =J42*J24 -> -0.018738464 | K41: =K42*K24 -> -0.016623601 | L41: =L42*L24 -> -0.014631167 | M41: =M42*M24 -> -0.012475852 | N41: =N42*N24 -> -0.011123128
C42: % of change in revenue | G42: =G41/G24 -> -0.088217286 | H42: =H41/H24 -> -0.13394582 | I42: =I41/I24 -> -0.1729283 | J42: =AVERAGE(G42:I42) -> -0.13169713 | K42: =J42 -> -0.13169713 | L42: =K42 -> -0.13169713 | M42: =L42 -> -0.13169713 | N42: =M42 -> -0.13169713
B44: DCF
B45: NOPAT | J45: =J26-J29 -> 94412.725 | K45: =K26-K29 -> 98563.128 | L45: =L26-L29 -> 112997.33 | M45: =M26-M29 -> 124305.37 | N45: =N26-N29 -> 119694.07
A46: + | B46: D&A | J46: =J33 -> 36104.134 | K46: =K33 -> 51693.773 | L46: =L33 -> 47881.139 | M46: =M33 -> 40333.169 | N46: =N33 -> 32853.378
A47: - | B47: Capex | J47: =J37 -> 85000 | K47: =K37 -> 95729.209 | L47: =L37 -> 85502.035 | M47: =M37 -> 82106.808 | N47: =N37 -> 77169.336
A48: - | B48: Change in NWC | J48: =J40 -> -7487.499 | K48: =K40 -> -7480.8931 | L48: =L40 -> -7315.7574 | M48: =M40 -> -6829.0161 | N48: =N40 -> -6602.803
...

Sheet Wacc
A1: WACC Calculations
B2: Total Debt: | C2: 23607
B3: Weighted Cost of Debt: | C3: 0.032
B4: % Debt: | C4: =C2/C14 -> 0.015881935
B5: Tax Rate: | C5: 0.21
B7: Equity Value: | C7: =5820*251.34 -> 1462798.8
B8: Cost of Equity: | C8: =C10+C11*C12 -> 0.08
B9: % Equity: | C9: =C7/C14 -> 0.98411807
B10: Risk-Free Rate: | C10: 0.0398 | D10: 10Y yield
B11: Beta: | C11: 1
B12: Market-Risk Premium: | C12: =8%-C10 -> 0.0402
B14: Debt + Equity: | C14: =C2+C7 -> 1486405.8
B16: WACC: | C16: =C8*C9+C3*C4*(1-C5) -> 0.079130941
B18: Terminal Growth Rate | C18: 0.03
